File: BrushLab/data/Ankenman brushes_5a.txt
""
"Test Method","Ankenman Simplified Tensile.msm"
"Sample I. D.","Ankenman brushes.mss"
"Specimen Number","5"

"Time (s)","Load (lbf)","Crosshead (in)"

0.600,0,0.001
1.000,0,0.001
1.400,0,0.002
1.800,0,0.003
2.200,0,0.004
2.600,0,0.005
3.000,0,0.005
3.400,0,0.006
3.800,0,0.007
4.200,0,0.008
4.600,0,0.009
5.000,0,0.009
5.400,0,0.010
5.800,0,0.011
6.200,0,0.012
6.600,0,0.012
7.000,0,0.013
7.400,0,0.014
7.800,0,0.015
8.200,0,0.016
8.600,0,0.016
9.000,0,0.017
9.400,1,0.018
9.800,3,0.019
10.200,4,0.020
10.600,6,0.020
11.000,8,0.021
11.400,10,0.022
11.800,13,0.023
12.200,15,0.023
12.600,17,0.024
13.000,19,0.025
13.400,22,0.026
13.800,24,0.027
14.200,26,0.027
14.600,28,0.028
15.000,29,0.029
15.400,31,0.030
15.800,32,0.031
16.200,34,0.031
16.600,36,0.032
17.000,37,0.033
17.400,39,0.034
17.800,40,0.034
18.200,41,0.035
18.600,42,0.036
19.000,43,0.037
19.400,43,0.038
19.800,44,0.038
20.200,45,0.039
20.600,46,0.040
21.000,46,0.041
21.400,47,0.042
21.800,47,0.042
22.200,48,0.043
22.600,49,0.044
23.000,49,0.045
23.400,49,0.045
23.800,50,0.046
24.200,50,0.047
24.600,50,0.048
25.000,51,0.049
25.400,51,0.049
25.800,51,0.050
26.200,52,0.051
26.600,52,0.052
27.000,52,0.053
27.400,53,0.053
27.800,53,0.054
28.200,53,0.055
28.600,53,0.056
29.000,54,0.057
29.400,54,0.057
29.800,54,0.058
30.200,55,0.059
30.600,55,0.060
31.000,55,0.060
31.400,56,0.061
31.800,56,0.062
32.200,56,0.063
32.600,56,0.064
33.000,57,0.064
33.400,57,0.065
33.800,57,0.066
34.200,57,0.067
34.600,58,0.068
35.000,58,0.068
35.400,58,0.069
35.800,58,0.070
36.200,59,0.071
36.600,59,0.071
37.000,59,0.072
37.400,59,0.073
37.800,60,0.074
38.200,60,0.075
38.600,60,0.075
39.000,60,0.076
39.400,60,0.077
39.800,61,0.078
40.200,61,0.079
40.600,61,0.079
41.000,61,0.080
41.400,62,0.081
41.800,62,0.082
42.200,62,0.083
42.600,62,0.083
43.000,62,0.084
43.400,63,0.085
43.800,63,0.086
44.200,63,0.086
44.600,64,0.087
45.000,64,0.088
45.400,64,0.089
45.800,64,0.090
46.200,64,0.090
46.600,65,0.091
47.000,65,0.092
47.400,65,0.093
47.800,65,0.094
48.200,65,0.094
48.600,66,0.095
49.000,66,0.096
49.400,66,0.097
49.800,66,0.097
50.200,66,0.098
50.600,67,0.099
51.000,67,0.100
51.400,67,0.101
51.800,67,0.101
52.200,68,0.102
52.600,68,0.103
53.000,68,0.104
53.400,68,0.105
53.800,68,0.105
54.200,68,0.106
54.600,69,0.107
55.000,69,0.108
55.400,69,0.108
55.800,70,0.109
56.200,70,0.110
56.600,70,0.111
57.000,70,0.112
57.400,70,0.112
57.800,71,0.113
58.200,71,0.114
58.600,71,0.115
59.000,71,0.116
59.400,71,0.116
59.800,72,0.117
60.200,72,0.118
60.600,72,0.119
61.000,72,0.119
61.400,73,0.120
61.800,73,0.121
62.200,73,0.122
62.600,74,0.123
63.000,74,0.123
63.400,74,0.124
63.800,74,0.125
64.200,74,0.126
64.600,75,0.127
65.000,75,0.127
65.400,75,0.128
65.800,76,0.129
66.200,76,0.130
66.600,77,0.131
67.000,77,0.131
67.400,77,0.132
67.800,78,0.133
68.200,79,0.134
68.600,79,0.134
69.000,79,0.135
69.400,80,0.136
69.800,81,0.137
70.200,81,0.138
70.600,82,0.138
71.000,82,0.139
71.400,83,0.140
71.800,83,0.141
72.200,84,0.142
72.600,84,0.142
73.000,85,0.143
73.400,85,0.144
73.800,85,0.145
74.200,86,0.145
74.600,86,0.146
75.000,87,0.147
75.400,88,0.148
75.800,88,0.149
76.200,89,0.149
76.600,89,0.150
77.000,89,0.151
77.400,90,0.152
77.800,91,0.153
78.200,91,0.153
78.600,92,0.154
79.000,92,0.155
79.400,93,0.156
79.800,93,0.157
80.200,93,0.157
80.600,94,0.158
81.000,95,0.159
81.400,95,0.160
81.800,96,0.160
82.200,96,0.161
82.600,97,0.162
83.000,97,0.163
83.400,97,0.164
83.800,98,0.164
84.200,99,0.165
84.600,99,0.166
85.000,99,0.167
85.400,100,0.168
85.800,100,0.168
86.200,101,0.169
86.600,101,0.170
87.000,102,0.171
87.400,102,0.171
87.800,103,0.172
88.200,103,0.173
88.600,104,0.174
89.000,104,0.175
89.400,105,0.175
89.800,105,0.176
90.200,106,0.177
90.600,106,0.178
91.000,107,0.179
91.400,107,0.179
91.800,108,0.180
92.200,108,0.181
92.600,108,0.182
93.000,109,0.183
93.400,110,0.183
93.800,110,0.184
94.200,110,0.185
94.600,111,0.186
95.000,112,0.186
95.400,112,0.187
95.800,113,0.188
96.200,113,0.189
96.600,113,0.190
97.000,114,0.190
97.400,114,0.191
97.800,115,0.192
98.200,115,0.193
98.600,116,0.194
99.000,117,0.194
99.400,117,0.195
99.800,117,0.196
100.200,118,0.197
100.600,118,0.197
101.000,119,0.198
101.400,119,0.199
101.800,120,0.200
102.200,120,0.201
102.600,121,0.201
103.000,121,0.202
103.400,122,0.203
103.800,122,0.204
104.200,123,0.205
104.600,124,0.205
105.000,124,0.206
105.400,124,0.207
105.800,125,0.208
106.200,126,0.208
106.600,126,0.209
107.000,126,0.210
107.400,127,0.211
107.800,127,0.212
108.200,128,0.212
108.600,128,0.213
109.000,129,0.214
109.400,129,0.215
109.800,130,0.216
110.200,130,0.216
110.600,131,0.217
111.000,132,0.218
111.400,132,0.219
111.800,133,0.220
112.200,133,0.220
112.600,133,0.221
113.000,134,0.222
113.400,134,0.223
113.800,135,0.223
114.200,135,0.224
114.600,136,0.225
115.000,136,0.226
115.400,137,0.227
115.800,137,0.227
116.200,138,0.228
116.600,138,0.229
117.000,139,0.230
117.400,139,0.231
117.800,140,0.231
118.200,140,0.232
118.600,141,0.233
119.000,141,0.234
119.400,142,0.234
119.800,142,0.235
120.200,143,0.236
120.600,143,0.237
121.000,144,0.238
121.400,144,0.238
121.800,145,0.239
122.200,145,0.240
122.600,146,0.241
123.000,146,0.242
123.400,147,0.242
123.800,147,0.243
124.200,148,0.244
124.600,148,0.245
125.000,148,0.246
125.400,149,0.246
125.800,149,0.247
126.200,150,0.248
126.600,150,0.249
127.000,151,0.249
127.400,151,0.250
127.800,152,0.251
128.200,152,0.252
128.600,153,0.253
129.000,153,0.253
129.400,154,0.254
129.800,154,0.255
130.200,155,0.256
130.600,155,0.257
131.000,155,0.257
131.400,156,0.258
131.800,156,0.259
132.200,157,0.260
132.600,157,0.260
133.000,158,0.261
133.400,158,0.262
133.800,159,0.263
134.200,159,0.264
134.600,160,0.264
135.000,160,0.265
135.400,161,0.266
135.800,161,0.267
136.200,161,0.268
136.600,162,0.268
137.000,162,0.269
137.400,163,0.270
137.800,163,0.271
138.200,163,0.271
138.600,164,0.272
139.000,164,0.273
139.400,165,0.274
139.800,165,0.275
140.200,166,0.275
140.600,166,0.276
141.000,166,0.277
141.400,167,0.278
141.800,167,0.279
142.200,168,0.279
142.600,168,0.280
143.000,169,0.281
143.400,169,0.282
143.800,169,0.282
144.200,170,0.283
144.600,170,0.284
145.000,170,0.285
145.400,171,0.286
145.800,171,0.286
146.200,172,0.287
146.600,172,0.288
147.000,172,0.289
147.400,173,0.290
147.800,173,0.290
148.200,174,0.291
148.600,174,0.292
149.000,174,0.293
149.400,175,0.294
149.800,175,0.294
150.200,175,0.295
150.600,176,0.296
151.000,176,0.297
151.400,176,0.297
151.800,177,0.298
152.200,177,0.299
152.600,178,0.300
153.000,178,0.301
153.400,178,0.301
153.800,179,0.302
154.200,179,0.303
154.600,179,0.304
155.000,180,0.305
155.400,180,0.305
155.800,180,0.306
156.200,181,0.307
156.600,181,0.308
157.000,181,0.308
157.400,182,0.309
157.800,182,0.310
158.200,182,0.311
158.600,182,0.312
159.000,183,0.312
159.400,183,0.313
159.800,183,0.314
160.200,184,0.315
160.600,184,0.316
161.000,184,0.316
161.400,185,0.317
161.800,185,0.318
162.200,185,0.319
162.600,185,0.319
163.000,186,0.320
163.400,186,0.321
163.800,186,0.322
164.200,186,0.323
164.600,187,0.323
165.000,187,0.324
165.400,187,0.325
165.800,187,0.326
166.200,188,0.327
166.600,188,0.327
167.000,188,0.328
167.400,188,0.329
167.800,188,0.330
168.200,189,0.331
168.600,189,0.331
169.000,189,0.332
169.400,189,0.333
169.800,190,0.334
170.200,190,0.334
170.600,190,0.335
171.000,190,0.336
171.400,190,0.337
171.800,190,0.338
172.200,190,0.338
172.600,191,0.339
173.000,191,0.340
173.400,191,0.341
173.800,191,0.342
174.200,191,0.342
174.600,192,0.343
175.000,192,0.344
175.400,192,0.345
175.800,192,0.345
176.200,192,0.346
176.600,192,0.347
177.000,192,0.348
177.400,192,0.349
177.800,193,0.349
178.200,193,0.350
178.600,193,0.351
179.000,193,0.352
179.400,193,0.353
179.800,193,0.353
180.200,193,0.354
180.600,193,0.355
181.000,193,0.356
181.400,193,0.357
181.800,194,0.357
182.200,194,0.358
182.600,194,0.359
183.000,194,0.360
183.400,194,0.360
183.800,194,0.361
184.200,194,0.362
184.600,194,0.363
185.000,194,0.364
185.400,194,0.364
185.800,194,0.365
186.200,194,0.366
186.600,195,0.367
187.000,195,0.368
187.400,195,0.368
187.800,195,0.369
188.200,195,0.370
188.600,195,0.371
189.000,195,0.371
189.400,195,0.372
189.800,195,0.373
190.200,195,0.374
190.600,195,0.375
191.000,195,0.375
191.400,195,0.376
191.800,195,0.377
192.200,195,0.378
192.600,195,0.379
193.000,195,0.379
193.400,195,0.380
193.800,196,0.381
194.200,196,0.382
194.600,196,0.383
195.000,196,0.383
195.400,196,0.384
195.800,196,0.385
196.200,196,0.386
196.600,196,0.386
197.000,196,0.387
197.400,196,0.388
197.800,196,0.389
198.200,196,0.390
198.600,196,0.390
199.000,196,0.391
199.400,196,0.392
199.800,196,0.393
200.200,196,0.394
200.600,196,0.394
201.000,196,0.395
201.400,196,0.396
201.800,196,0.397
202.200,196,0.397
202.600,196,0.398
203.000,197,0.399
203.400,197,0.400
203.800,197,0.401
204.200,197,0.401
204.600,197,0.402
205.000,197,0.403
205.400,197,0.404
205.800,197,0.405
206.200,197,0.405
206.600,197,0.406
207.000,197,0.407
207.400,197,0.408
207.800,197,0.409
208.200,197,0.409
208.600,197,0.410
209.000,197,0.411
209.400,197,0.412
209.800,197,0.412
210.200,197,0.413
210.600,197,0.414
211.000,197,0.415
211.400,197,0.416
211.800,197,0.416
212.200,197,0.417
212.600,197,0.418
213.000,197,0.419
213.400,197,0.420
213.800,197,0.420
214.200,197,0.421
214.600,197,0.422
215.000,197,0.423
215.400,197,0.423
215.800,197,0.424
216.200,197,0.425
216.600,198,0.426
217.000,197,0.427
217.400,197,0.427
217.800,198,0.428
218.200,198,0.429
218.600,198,0.430
219.000,198,0.431
219.400,198,0.431
219.800,198,0.432
220.200,198,0.433
220.600,198,0.434
221.000,198,0.434
221.400,198,0.435
221.800,198,0.436
222.200,198,0.437
222.600,198,0.438
223.000,198,0.438
223.400,198,0.439
223.800,198,0.440
224.200,198,0.441
224.600,198,0.442
225.000,198,0.442
225.400,198,0.443
225.800,198,0.444
226.200,198,0.445
226.600,198,0.445
227.000,198,0.446
227.400,198,0.447
227.800,198,0.448
228.200,198,0.449
228.600,198,0.449
229.000,198,0.450
229.400,198,0.451
229.800,198,0.452
230.200,198,0.453
230.600,198,0.453
231.000,198,0.454
231.400,198,0.455
231.800,198,0.456
232.200,198,0.456
232.600,198,0.457
233.000,198,0.458
233.400,198,0.459
233.800,198,0.460
234.200,198,0.460
234.600,198,0.461
235.000,198,0.462
235.400,198,0.463
235.800,198,0.464
236.200,198,0.464
236.600,198,0.465
237.000,198,0.466
237.400,198,0.467
237.800,198,0.468
238.200,198,0.468
238.600,198,0.469
239.000,198,0.470
239.400,198,0.471
239.800,198,0.471
240.200,198,0.472
240.600,198,0.473
241.000,198,0.474
241.400,198,0.475
241.800,198,0.475
242.200,198,0.476
242.600,198,0.477
243.000,198,0.478
243.400,198,0.479
243.800,198,0.479
244.200,198,0.480
244.600,198,0.481
245.000,198,0.482
245.400,198,0.482
245.800,199,0.483
246.200,199,0.484
246.600,199,0.485
247.000,198,0.486
247.400,198,0.486
247.800,198,0.487
248.200,198,0.488
248.600,198,0.489
249.000,198,0.490
249.400,198,0.490
249.800,198,0.491
250.200,198,0.492
250.600,198,0.493
251.000,198,0.493
251.400,198,0.494
251.800,198,0.495
252.200,198,0.496
252.600,198,0.497
253.000,198,0.497
253.400,199,0.498
253.800,198,0.499
254.200,198,0.500
254.600,198,0.501
255.000,198,0.501
255.400,198,0.502
255.800,198,0.503
256.200,198,0.504
256.600,198,0.505
257.000,198,0.505
257.400,198,0.506
257.800,198,0.507
258.200,198,0.508
258.600,198,0.508
259.000,198,0.509
259.400,198,0.510
259.800,198,0.511
260.200,198,0.512
260.600,198,0.512
261.000,199,0.513
261.400,198,0.514
261.800,198,0.515
262.200,198,0.516
262.600,198,0.516
263.000,198,0.517
263.400,198,0.518
263.800,198,0.519
264.200,198,0.519
264.600,198,0.520
265.000,198,0.521
265.400,198,0.522
265.800,198,0.523
266.200,198,0.523
266.600,198,0.524
267.000,198,0.525
267.400,198,0.526
267.800,198,0.527
268.200,198,0.527
268.600,198,0.528
269.000,198,0.529
269.400,198,0.530
269.800,198,0.530
270.200,198,0.531
270.600,198,0.532
271.000,198,0.533
271.400,198,0.534
271.800,198,0.534
272.200,198,0.535
272.600,198,0.536
273.000,198,0.537
273.400,198,0.538
273.800,198,0.538
274.200,198,0.539
274.600,198,0.540
275.000,198,0.541
275.400,198,0.542
275.800,198,0.542
276.200,198,0.543
276.600,198,0.544
277.000,198,0.545
277.400,198,0.545
277.800,198,0.546
278.200,198,0.547
278.600,198,0.548
279.000,198,0.549
279.400,198,0.549
279.800,198,0.550
280.200,198,0.551
280.600,198,0.552
281.000,198,0.553
281.400,198,0.553
281.800,198,0.554
282.200,198,0.555
282.600,198,0.556
283.000,198,0.557
283.400,198,0.557
283.800,198,0.558
284.200,198,0.559
284.600,198,0.560
285.000,198,0.560
285.400,198,0.561
285.800,198,0.562
286.200,198,0.563
286.600,198,0.564
287.000,198,0.564
287.400,198,0.565
287.800,198,0.566
288.200,198,0.567
288.600,197,0.568
289.000,198,0.568
289.400,197,0.569
289.800,198,0.570
290.200,197,0.571
290.600,197,0.571
291.000,197,0.572
291.400,197,0.573
291.800,197,0.574
292.200,197,0.575
292.600,197,0.575
293.000,197,0.576
293.400,197,0.577
293.800,197,0.578
294.200,197,0.579
294.600,197,0.579
295.000,197,0.580
295.400,197,0.581
295.800,197,0.582
296.200,197,0.582
296.600,197,0.583
297.000,197,0.584
297.400,197,0.585
297.800,197,0.586
298.200,197,0.586
298.600,197,0.587
299.000,197,0.588
299.400,197,0.589
299.800,197,0.590
300.200,197,0.590
300.600,197,0.591
301.000,197,0.592
301.400,197,0.593
301.800,197,0.593
302.200,197,0.594
302.600,197,0.595
303.000,197,0.596
303.400,197,0.597
303.800,197,0.597
304.200,197,0.598
304.600,197,0.599
305.000,197,0.600
305.400,197,0.601
305.800,197,0.601
306.200,196,0.602
306.600,197,0.603
307.000,196,0.604
307.400,196,0.604
307.800,196,0.605
308.200,196,0.606
308.600,196,0.607
309.000,196,0.608
309.400,196,0.608
309.800,196,0.609
310.200,196,0.610
310.600,196,0.611
311.000,196,0.612
311.400,196,0.612
311.800,196,0.613
312.200,196,0.614
312.600,196,0.615
313.000,196,0.616
313.400,196,0.616
313.800,196,0.617
314.200,196,0.618
314.600,196,0.619
315.000,196,0.619
315.400,196,0.620
315.800,196,0.621
316.200,196,0.622
316.600,196,0.623
317.000,196,0.623
317.400,196,0.624
317.800,196,0.625
318.200,196,0.626
318.600,196,0.627
319.000,196,0.627
319.400,196,0.628
319.800,196,0.629
320.200,196,0.630
320.600,196,0.630
321.000,196,0.631
321.400,196,0.632
321.800,196,0.633
322.200,196,0.634
322.600,195,0.634
323.000,195,0.635
323.400,195,0.636
323.800,196,0.637
324.200,195,0.638
324.600,195,0.638
325.000,195,0.639
325.400,195,0.640
325.800,195,0.641
326.200,195,0.642
326.600,195,0.642
327.000,195,0.643
327.400,195,0.644
327.800,195,0.645
328.200,195,0.645
328.600,195,0.646
329.000,195,0.647
329.400,195,0.648
329.800,195,0.649
330.200,195,0.649
330.600,195,0.650
331.000,195,0.651
331.400,195,0.652
331.800,195,0.653
332.200,195,0.653
332.600,195,0.654
333.000,195,0.655
333.400,195,0.656
333.800,195,0.656
334.200,195,0.657
334.600,195,0.658
335.000,195,0.659
335.400,195,0.660
335.800,194,0.660
336.200,195,0.661
336.600,194,0.662
337.000,194,0.663
337.400,194,0.664
337.800,194,0.664
338.200,194,0.665
338.600,194,0.666
339.000,194,0.667
339.400,194,0.668
339.800,194,0.668
340.200,194,0.669
340.600,194,0.670
341.000,194,0.671
341.400,194,0.671
341.800,194,0.672
342.200,194,0.673
342.600,194,0.674
343.000,194,0.675
343.400,194,0.675
343.800,194,0.676
344.200,194,0.677
344.600,194,0.678
345.000,194,0.679
345.400,194,0.679
345.800,194,0.680
346.200,194,0.681
346.600,194,0.682
347.000,193,0.682
347.400,194,0.683
347.800,193,0.684
348.200,193,0.685
348.600,193,0.686
349.000,193,0.686
349.400,193,0.687
349.800,193,0.688
350.200,193,0.689
350.600,193,0.690
351.000,193,0.690
351.400,193,0.691
351.800,193,0.692
352.200,193,0.693
352.600,193,0.693
353.000,193,0.694
353.400,193,0.695
353.800,193,0.696
354.200,193,0.697
354.600,193,0.697
355.000,193,0.698
355.400,193,0.699
355.800,193,0.700
356.200,193,0.701
356.600,193,0.701
357.000,193,0.702
357.400,193,0.703
357.800,193,0.704
358.200,193,0.705
358.600,192,0.705
359.000,193,0.706
359.400,192,0.707
359.800,192,0.708
360.200,192,0.708
360.600,192,0.709
361.000,192,0.710
361.400,192,0.711
361.800,192,0.712
362.200,192,0.712
362.600,192,0.713
363.000,192,0.714
363.400,192,0.715
363.800,192,0.716
364.200,192,0.716
364.600,192,0.717
365.000,192,0.718
365.400,192,0.719
365.800,192,0.719
366.200,192,0.720
366.600,192,0.721
367.000,192,0.722
367.400,192,0.723
367.800,192,0.723
368.200,192,0.724
368.600,192,0.725
369.000,192,0.726
369.400,192,0.727
369.800,192,0.727
370.200,191,0.728
370.600,191,0.729
371.000,191,0.730
371.400,191,0.731
371.800,191,0.731
372.200,191,0.732
372.600,191,0.733
373.000,191,0.734
373.400,191,0.734
373.800,191,0.735
374.200,191,0.736
374.600,191,0.737
375.000,191,0.738
375.400,191,0.738
375.800,191,0.739
376.200,191,0.740
376.600,191,0.741
377.000,191,0.742
377.400,191,0.742
377.800,191,0.743
378.200,191,0.744
378.600,191,0.745
379.000,191,0.745
379.400,191,0.746
379.800,191,0.747
380.200,191,0.748
380.600,191,0.749
381.000,190,0.749
381.400,190,0.750
381.800,190,0.751
382.200,191,0.752
382.600,190,0.753
383.000,190,0.753
383.400,190,0.754
383.800,190,0.755
384.200,190,0.756
384.600,190,0.756
385.000,190,0.757
385.400,190,0.758
385.800,190,0.759
386.200,190,0.760
386.600,190,0.760
387.000,190,0.761
387.400,190,0.762
387.800,190,0.763
388.200,190,0.764
388.600,190,0.764
389.000,190,0.765
389.400,188,0.766
389.800,188,0.767
390.200,188,0.768
390.600,188,0.768
391.000,188,0.769
391.400,188,0.770
391.800,188,0.771
392.200,188,0.771
392.600,188,0.772
393.000,188,0.773
393.400,188,0.774
393.800,188,0.775
394.200,188,0.775
394.600,188,0.776
395.000,188,0.777
395.400,188,0.778
395.800,188,0.779
396.200,188,0.779
396.600,188,0.780
397.000,188,0.781
397.400,188,0.782
397.800,188,0.783
398.200,188,0.783
398.600,188,0.784
399.000,188,0.785
399.400,188,0.786
399.800,188,0.786
400.200,188,0.787
400.600,188,0.788
401.000,188,0.789
401.400,188,0.790
401.800,188,0.790
402.200,188,0.791
402.600,188,0.792
403.000,188,0.793
403.400,188,0.794
403.800,188,0.794
404.200,188,0.795
404.600,188,0.796
405.000,188,0.797
405.400,188,0.797
405.800,188,0.798
406.200,188,0.799
406.600,188,0.800
407.000,188,0.801
407.400,187,0.801
407.800,187,0.802
408.200,187,0.803
408.600,187,0.804
409.000,187,0.805
409.400,68,0.805
409.800,68,0.806
410.200,69,0.807
410.600,69,0.808
411.000,69,0.809
411.400,70,0.809
411.800,69,0.810
412.200,70,0.811
412.600,70,0.812
413.000,70,0.812
413.400,70,0.813
413.800,70,0.814
414.200,71,0.815
414.600,71,0.816
415.000,71,0.816
415.400,71,0.817
415.800,71,0.818
416.200,71,0.819
416.600,71,0.820
417.000,72,0.820
417.400,72,0.821
417.800,72,0.822
418.200,72,0.823
418.600,72,0.823
419.000,72,0.824
419.400,73,0.825
419.800,73,0.826
420.200,73,0.827
420.600,73,0.827
421.000,73,0.828
421.400,73,0.829
421.800,73,0.830
422.200,73,0.831
422.600,73,0.831
423.000,60,0.832
423.020,3,0.832