File: BrushLab/data/Ankenman brushes_1.txt
""
"Test Method","Ankenman Simplified Tensile.msm"
"Sample I. D.","Ankenman brushes.mss"
"Specimen Number","1"

"Time (s)","Load (lbf)","Crosshead (in)"

0.400,0,0.000
0.800,0,0.000
1.200,0,0.001
1.600,0,0.001
2.000,0,0.002
2.400,0,0.002
2.800,0,0.002
3.200,0,0.003
3.600,0,0.003
4.000,0,0.004
4.400,0,0.004
4.800,0,0.004
5.200,0,0.005
5.600,0,0.005
6.000,0,0.006
6.400,0,0.006
6.800,0,0.006
7.200,0,0.007
7.600,0,0.007
8.000,1,0.008
8.400,1,0.008
8.800,1,0.008
9.200,1,0.009
9.600,2,0.009
10.000,2,0.010
10.400,3,0.010
10.800,3,0.010
11.200,4,0.011
11.600,5,0.011
12.000,6,0.011
12.400,7,0.012
12.800,7,0.012
13.200,8,0.013
13.600,10,0.013
14.000,11,0.013
14.400,12,0.014
14.800,13,0.014
15.200,14,0.015
15.600,15,0.015
16.000,16,0.015
16.400,18,0.016
16.800,19,0.016
17.200,20,0.017
17.600,21,0.017
18.000,23,0.017
18.400,24,0.018
18.800,25,0.018
19.200,26,0.019
19.600,28,0.019
20.000,29,0.019
20.400,30,0.020
20.800,31,0.020
21.200,32,0.021
21.600,33,0.021
22.000,35,0.021
22.400,36,0.022
22.800,37,0.022
23.200,38,0.022
23.600,39,0.023
24.000,40,0.023
24.400,42,0.024
24.800,43,0.024
25.200,44,0.024
25.600,45,0.025
26.000,46,0.025
26.400,46,0.026
26.800,47,0.026
27.200,48,0.026
27.600,49,0.027
28.000,49,0.027
28.400,50,0.028
28.800,51,0.028
29.200,51,0.028
29.600,52,0.029
30.000,52,0.029
30.400,53,0.030
30.800,53,0.030
31.200,54,0.030
31.600,54,0.031
32.000,55,0.031
32.400,55,0.032
32.800,56,0.032
33.200,56,0.032
33.600,57,0.033
34.000,57,0.033
34.400,57,0.034
34.800,58,0.034
35.200,58,0.034
35.600,58,0.035
36.000,59,0.035
36.400,59,0.035
36.800,59,0.036
37.200,60,0.036
37.600,60,0.037
38.000,60,0.037
38.400,60,0.037
38.800,61,0.038
39.200,61,0.038
39.600,61,0.039
40.000,62,0.039
40.400,62,0.039
40.800,62,0.040
41.200,62,0.040
41.600,62,0.041
42.000,63,0.041
42.400,63,0.041
42.800,63,0.042
43.200,63,0.042
43.600,64,0.043
44.000,64,0.043
44.400,64,0.043
44.800,64,0.044
45.200,64,0.044
45.600,65,0.045
46.000,65,0.045
46.400,65,0.045
46.800,65,0.046
47.200,66,0.046
47.600,66,0.046
48.000,66,0.047
48.400,66,0.047
48.800,67,0.048
49.200,67,0.048
49.600,67,0.048
50.000,67,0.049
50.400,67,0.049
50.800,68,0.050
51.200,68,0.050
51.600,68,0.050
52.000,68,0.051
52.400,68,0.051
52.800,69,0.052
53.200,69,0.052
53.600,69,0.052
54.000,69,0.053
54.400,70,0.053
54.800,70,0.054
55.200,70,0.054
55.600,70,0.054
56.000,70,0.055
56.400,71,0.055
56.800,71,0.056
57.200,71,0.056
57.600,71,0.056
58.000,71,0.057
58.400,72,0.057
58.800,72,0.058
59.200,72,0.058
59.600,72,0.058
60.000,72,0.059
60.400,73,0.059
60.800,73,0.059
61.200,73,0.060
61.600,73,0.060
62.000,73,0.061
62.400,74,0.061
62.800,74,0.061
63.200,74,0.062
63.600,74,0.062
64.000,75,0.063
64.400,75,0.063
64.800,75,0.063
65.200,75,0.064
65.600,75,0.064
66.000,76,0.065
66.400,76,0.065
66.800,76,0.065
67.200,76,0.066
67.600,76,0.066
68.000,77,0.067
68.400,77,0.067
68.800,77,0.067
69.200,77,0.068
69.600,77,0.068
70.000,78,0.069
70.400,78,0.069
70.800,78,0.069
71.200,78,0.070
71.600,78,0.070
72.000,79,0.071
72.400,79,0.071
72.800,79,0.071
73.200,79,0.072
73.600,79,0.072
74.000,80,0.072
74.400,80,0.073
74.800,80,0.073
75.200,80,0.074
75.600,81,0.074
76.000,81,0.074
76.400,81,0.075
76.800,81,0.075
77.200,82,0.076
77.600,82,0.076
78.000,81,0.076
78.400,82,0.077
78.800,82,0.077
79.200,83,0.078
79.600,83,0.078
80.000,83,0.078
80.400,83,0.079
80.800,83,0.079
81.200,84,0.080
81.600,84,0.080
82.000,83,0.080
82.400,84,0.081
82.800,84,0.081
83.200,85,0.082
83.600,84,0.082
84.000,85,0.082
84.400,85,0.083
84.800,85,0.083
85.200,85,0.083
85.600,86,0.084
86.000,86,0.084
86.400,86,0.085
86.800,86,0.085
87.200,86,0.085
87.600,87,0.086
88.000,87,0.086
88.400,87,0.087
88.800,87,0.087
89.200,88,0.087
89.600,88,0.088
90.000,88,0.088
90.400,88,0.089
90.800,88,0.089
91.200,89,0.089
91.600,89,0.090
92.000,89,0.090
92.400,89,0.091
92.800,89,0.091
93.200,90,0.091
93.600,90,0.092
94.000,90,0.092
94.400,90,0.093
94.800,90,0.093
95.200,91,0.093
95.600,91,0.094
96.000,91,0.094
96.400,91,0.094
96.800,91,0.095
97.200,92,0.095
97.600,92,0.096
98.000,92,0.096
98.400,92,0.096
98.800,92,0.097
99.200,93,0.097
99.600,93,0.098
100.000,93,0.098
100.400,93,0.098
100.800,94,0.099
101.200,94,0.099
101.600,94,0.100
102.000,94,0.100
102.400,94,0.100
102.800,95,0.101
103.200,95,0.101
103.600,95,0.102
104.000,95,0.102
104.400,95,0.102
104.800,96,0.103
105.200,96,0.103
105.600,96,0.104
106.000,96,0.104
106.400,96,0.104
106.800,97,0.105
107.200,97,0.105
107.600,97,0.105
108.000,97,0.106
108.400,97,0.106
108.800,98,0.107
109.200,98,0.107
109.600,98,0.107
110.000,98,0.108
110.400,98,0.108
110.800,99,0.109
111.200,99,0.109
111.600,99,0.109
112.000,99,0.110
112.400,99,0.110
112.800,100,0.111
113.200,100,0.111
113.600,100,0.111
114.000,100,0.112
114.400,101,0.112
114.800,101,0.113
115.200,101,0.113
115.600,101,0.113
116.000,101,0.114
116.400,101,0.114
116.800,102,0.115
117.200,102,0.115
117.600,102,0.115
118.000,102,0.116
118.400,102,0.116
118.800,103,0.117
119.200,103,0.117
119.600,103,0.117
120.000,103,0.118
120.400,104,0.118
120.800,104,0.118
121.200,104,0.119
121.600,104,0.119
122.000,104,0.120
122.400,105,0.120
122.800,105,0.120
123.200,105,0.121
123.600,105,0.121
124.000,105,0.122
124.400,106,0.122
124.800,106,0.122
125.200,106,0.123
125.600,106,0.123
126.000,106,0.124
126.400,106,0.124
126.800,107,0.124
127.200,107,0.125
127.600,107,0.125
128.000,107,0.126
128.400,108,0.126
128.800,108,0.126
129.200,108,0.127
129.600,108,0.127
130.000,108,0.128
130.400,109,0.128
130.800,109,0.128
131.200,109,0.129
131.600,109,0.129
132.000,109,0.129
132.400,110,0.130
132.800,110,0.130
133.200,110,0.131
133.600,110,0.131
134.000,110,0.131
134.400,111,0.132
134.800,111,0.132
135.200,111,0.133
135.600,111,0.133
136.000,112,0.133
136.400,112,0.134
136.800,112,0.134
137.200,112,0.135
137.600,112,0.135
138.000,113,0.135
138.400,113,0.136
138.800,113,0.136
139.200,113,0.137
139.600,113,0.137
140.000,114,0.137
140.400,114,0.138
140.800,114,0.138
141.200,114,0.139
141.600,114,0.139
142.000,115,0.139
142.400,115,0.140
142.800,115,0.140
143.200,115,0.141
143.600,115,0.141
144.000,116,0.141
144.400,116,0.142
144.800,116,0.142
145.200,116,0.143
145.600,116,0.143
146.000,117,0.143
146.400,117,0.144
146.800,117,0.144
147.200,117,0.144
147.600,117,0.145
148.000,118,0.145
148.400,118,0.146
148.800,118,0.146
149.200,118,0.146
149.600,118,0.147
150.000,119,0.147
150.400,119,0.148
150.800,119,0.148
151.200,119,0.148
151.600,120,0.149
152.000,120,0.149
152.400,120,0.150
152.800,120,0.150
153.200,120,0.150
153.600,121,0.151
154.000,121,0.151
154.400,121,0.152
154.800,121,0.152
155.200,121,0.152
155.600,122,0.153
156.000,122,0.153
156.400,122,0.154
156.800,122,0.154
157.200,122,0.154
157.600,123,0.155
158.000,123,0.155
158.400,123,0.155
158.800,123,0.156
159.200,123,0.156
159.600,124,0.157
160.000,124,0.157
160.400,124,0.157
160.800,124,0.158
161.200,124,0.158
161.600,125,0.159
162.000,125,0.159
162.400,125,0.159
162.800,125,0.160
163.200,126,0.160
163.600,126,0.161
164.000,126,0.161
164.400,126,0.161
164.800,126,0.162
165.200,126,0.162
165.600,127,0.163
166.000,127,0.163
166.400,127,0.163
166.800,127,0.164
167.200,128,0.164
167.600,128,0.165
168.000,128,0.165
168.400,128,0.165
168.800,128,0.166
169.200,129,0.166
169.600,129,0.167
170.000,129,0.167
170.400,129,0.167
170.800,130,0.168
171.200,130,0.168
171.600,130,0.169
172.000,130,0.169
172.400,131,0.169
172.800,131,0.170
173.200,131,0.170
173.600,131,0.170
174.000,131,0.171
174.400,132,0.171
174.800,132,0.172
175.200,132,0.172
175.600,132,0.172
176.000,133,0.173
176.400,133,0.173
176.800,133,0.174
177.200,133,0.174
177.600,134,0.174
178.000,134,0.175
178.400,134,0.175
178.800,135,0.176
179.200,135,0.176
179.600,135,0.176
180.000,135,0.177
180.400,136,0.177
180.800,136,0.178
181.200,136,0.178
181.600,136,0.178
182.000,137,0.179
182.400,137,0.179
182.800,137,0.180
183.200,137,0.180
183.600,138,0.180
184.000,138,0.181
184.400,138,0.181
184.800,139,0.181
185.200,139,0.182
185.600,139,0.182
186.000,139,0.183
186.400,140,0.183
186.800,140,0.183
187.200,140,0.184
187.600,140,0.184
188.000,141,0.185
188.400,141,0.185
188.800,141,0.185
189.200,141,0.186
189.600,142,0.186
190.000,142,0.187
190.400,142,0.187
190.800,143,0.187
191.200,143,0.188
191.600,143,0.188
192.000,143,0.189
192.400,144,0.189
192.800,144,0.189
193.200,144,0.190
193.600,144,0.190
194.000,145,0.191
194.400,145,0.191
194.800,145,0.191
195.200,146,0.192
195.600,146,0.192
196.000,146,0.193
196.400,146,0.193
196.800,147,0.193
197.200,147,0.194
197.600,147,0.194
198.000,147,0.194
198.400,148,0.195
198.800,148,0.195
199.200,148,0.196
199.600,148,0.196
200.000,149,0.196
200.400,149,0.197
200.800,149,0.197
201.200,150,0.198
201.600,150,0.198
202.000,150,0.198
202.400,150,0.199
202.800,151,0.199
203.200,151,0.200
203.600,151,0.200
204.000,151,0.200
204.400,152,0.201
204.800,152,0.201
205.200,152,0.202
205.600,152,0.202
206.000,153,0.202
206.400,153,0.203
206.800,153,0.203
207.200,153,0.204
207.600,154,0.204
208.000,154,0.204
208.400,154,0.205
208.800,155,0.205
209.200,155,0.206
209.600,155,0.206
210.000,155,0.206
210.400,156,0.207
210.800,156,0.207
211.200,156,0.207
211.600,156,0.208
212.000,156,0.208
212.400,157,0.209
212.800,157,0.209
213.200,157,0.209
213.600,158,0.210
214.000,158,0.210
214.400,158,0.211
214.800,158,0.211
215.200,159,0.211
215.600,159,0.212
216.000,159,0.212
216.400,159,0.213
216.800,160,0.213
217.200,160,0.213
217.600,160,0.214
218.000,160,0.214
218.400,161,0.215
218.800,161,0.215
219.200,161,0.215
219.600,161,0.216
220.000,162,0.216
220.400,162,0.217
220.800,162,0.217
221.200,162,0.217
221.600,163,0.218
222.000,163,0.218
222.400,163,0.219
222.800,163,0.219
223.200,164,0.219
223.600,164,0.220
224.000,164,0.220
224.400,164,0.220
224.800,165,0.221
225.200,165,0.221
225.600,165,0.222
226.000,165,0.222
226.400,166,0.222
226.800,166,0.223
227.200,166,0.223
227.600,166,0.224
228.000,166,0.224
228.400,167,0.224
228.800,167,0.225
229.200,167,0.225
229.600,167,0.226
230.000,168,0.226
230.400,168,0.226
230.800,168,0.227
231.200,168,0.227
231.600,169,0.228
232.000,169,0.228
232.400,169,0.228
232.800,169,0.229
233.200,170,0.229
233.600,170,0.230
234.000,170,0.230
234.400,170,0.230
234.800,171,0.231
235.200,171,0.231
235.600,171,0.232
236.000,171,0.232
236.400,171,0.232
236.800,172,0.233
237.200,172,0.233
237.600,172,0.233
238.000,172,0.234
238.400,173,0.234
238.800,173,0.235
239.200,173,0.235
239.600,173,0.235
240.000,174,0.236
240.400,174,0.236
240.800,174,0.237
241.200,174,0.237
241.600,174,0.237
242.000,175,0.238
242.400,175,0.238
242.800,175,0.239
243.200,175,0.239
243.600,176,0.239
244.000,176,0.240
244.400,176,0.240
244.800,176,0.241
245.200,177,0.241
245.600,177,0.241
246.000,177,0.242
246.400,177,0.242
246.800,178,0.243
247.200,178,0.243
247.600,178,0.243
248.000,178,0.244
248.400,178,0.244
248.800,179,0.245
249.200,179,0.245
249.600,179,0.245
250.000,179,0.246
250.400,179,0.246
250.800,180,0.246
251.200,180,0.247
251.600,180,0.247
252.000,180,0.248
252.400,181,0.248
252.800,181,0.248
253.200,181,0.249
253.600,181,0.249
254.000,181,0.250
254.400,182,0.250
254.800,182,0.250
255.200,182,0.251
255.600,182,0.251
256.000,183,0.252
256.400,183,0.252
256.800,183,0.252
257.200,183,0.253
257.600,183,0.253
258.000,184,0.254
258.400,184,0.254
258.800,184,0.254
259.200,184,0.255
259.600,185,0.255
260.000,185,0.256
260.400,185,0.256
260.800,185,0.256
261.200,185,0.257
261.600,186,0.257
262.000,186,0.257
262.400,186,0.258
262.800,186,0.258
263.200,186,0.259
263.600,187,0.259
264.000,187,0.259
264.400,187,0.260
264.800,187,0.260
265.200,187,0.261
265.600,188,0.261
266.000,188,0.261
266.400,188,0.262
266.800,188,0.262
267.200,188,0.263
267.600,189,0.263
268.000,189,0.263
268.400,189,0.264
268.800,189,0.264
269.200,189,0.265
269.600,190,0.265
270.000,190,0.265
270.400,190,0.266
270.800,190,0.266
271.200,191,0.267
271.600,191,0.267
272.000,191,0.267
272.400,191,0.268
272.800,191,0.268
273.200,191,0.268
273.600,192,0.269
274.000,192,0.269
274.400,192,0.270
274.800,192,0.270
275.200,192,0.270
275.600,193,0.271
276.000,193,0.271
276.400,193,0.272
276.800,193,0.272
277.200,193,0.272
277.600,194,0.273
278.000,194,0.273
278.400,194,0.274
278.800,194,0.274
279.200,194,0.274
279.600,194,0.275
280.000,195,0.275
280.400,195,0.276
280.800,195,0.276
281.200,195,0.276
281.600,195,0.277
282.000,196,0.277
282.400,196,0.278
282.800,196,0.278
283.200,196,0.278
283.600,196,0.279
284.000,196,0.279
284.400,197,0.280
284.800,197,0.280
285.200,197,0.280
285.600,197,0.281
286.000,197,0.281
286.400,197,0.281
286.800,198,0.282
287.200,198,0.282
287.600,198,0.283
288.000,198,0.283
288.400,198,0.283
288.800,199,0.284
289.200,199,0.284
289.600,199,0.285
290.000,199,0.285
290.400,199,0.285
290.800,199,0.286
291.200,199,0.286
291.600,200,0.287
292.000,200,0.287
292.400,200,0.287
292.800,200,0.288
293.200,200,0.288
293.600,200,0.289
294.000,201,0.289
294.400,201,0.289
294.800,201,0.290
295.200,201,0.290
295.600,201,0.291
296.000,201,0.291
296.400,201,0.291
296.800,202,0.292
297.200,202,0.292
297.600,202,0.293
298.000,202,0.293
298.400,202,0.293
298.800,202,0.294
299.200,202,0.294
299.600,202,0.294
300.000,203,0.295
300.400,203,0.295
300.800,203,0.296
301.200,203,0.296
301.600,203,0.296
302.000,203,0.297
302.400,204,0.297
302.800,204,0.298
303.200,204,0.298
303.600,204,0.298
304.000,204,0.299
304.400,204,0.299
304.800,204,0.300
305.200,205,0.300
305.600,205,0.300
306.000,205,0.301
306.400,205,0.301
306.800,205,0.302
307.200,205,0.302
307.600,205,0.302
308.000,205,0.303
308.400,206,0.303
308.800,206,0.304
309.200,206,0.304
309.600,206,0.304
310.000,206,0.305
310.400,206,0.305
310.800,206,0.305
311.200,206,0.306
311.600,207,0.306
312.000,207,0.307
312.400,207,0.307
312.800,207,0.307
313.200,207,0.308
313.600,207,0.308
314.000,207,0.309
314.400,207,0.309
314.800,208,0.309
315.200,208,0.310
315.600,208,0.310
316.000,208,0.311
316.400,208,0.311
316.800,208,0.311
317.200,208,0.312
317.600,208,0.312
318.000,208,0.313
318.400,209,0.313
318.800,209,0.313
319.200,209,0.314
319.600,209,0.314
320.000,209,0.315
320.400,209,0.315
320.800,209,0.315
321.200,209,0.316
321.600,209,0.316
322.000,209,0.316
322.400,210,0.317
322.800,210,0.317
323.200,210,0.318
323.600,210,0.318
324.000,210,0.318
324.400,210,0.319
324.800,210,0.319
325.200,210,0.320
325.600,210,0.320
326.000,210,0.320
326.400,211,0.321
326.800,211,0.321
327.200,211,0.322
327.600,211,0.322
328.000,211,0.322
328.400,211,0.323
328.800,211,0.323
329.200,211,0.324
329.600,211,0.324
330.000,211,0.324
330.400,211,0.325
330.800,212,0.325
331.200,212,0.326
331.600,212,0.326
332.000,212,0.326
332.400,212,0.327
332.800,212,0.327
333.200,212,0.328
333.600,212,0.328
334.000,212,0.328
334.400,212,0.329
334.800,212,0.329
335.200,213,0.330
335.600,213,0.330
336.000,213,0.330
336.400,213,0.331
336.800,213,0.331
337.200,213,0.331
337.600,213,0.332
338.000,213,0.332
338.400,213,0.333
338.800,213,0.333
339.200,213,0.333
339.600,213,0.334
340.000,213,0.334
340.400,213,0.335
340.800,213,0.335
341.200,214,0.335
341.600,214,0.336
342.000,214,0.336
342.400,214,0.337
342.800,214,0.337
343.200,214,0.337
343.600,214,0.338
344.000,214,0.338
344.400,214,0.339
344.800,214,0.339
345.200,214,0.339
345.600,214,0.340
346.000,214,0.340
346.400,214,0.341
346.800,215,0.341
347.200,215,0.341
347.600,215,0.342
348.000,215,0.342
348.400,215,0.342
348.800,215,0.343
349.200,215,0.343
349.600,215,0.344
350.000,215,0.344
350.400,215,0.344
350.800,215,0.345
351.200,215,0.345
351.600,215,0.346
352.000,215,0.346
352.400,215,0.346
352.800,215,0.347
353.200,216,0.347
353.600,216,0.348
354.000,216,0.348
354.400,216,0.348
354.800,216,0.349
355.200,216,0.349
355.600,216,0.350
356.000,216,0.350
356.400,216,0.350
356.800,215,0.351
357.200,215,0.351
357.510,8,0.351